Workbook

Sheet resumen_viscosidad_densidad
A1: system | B1: aroma_id | C1: aroma_name | D1: solvent_id | E1: solvent_name | F1: temperature_c | G1: molefrac_aroma | H1: density_g_cm3 | I1: v_excess_cm3 | J1: viscosity_mPas | K1: data_complete
A2: beta+2m3b2oh | B2: beta | C2: betaionone (trans) | D2: 2m3b2oh | E2: 2-methyl-3-buten-2-ol | F2: =IFERROR('dens_visc_beta+2m3b2oh'!B22,"") -> 20 | G2: =IFERROR('dens_visc_beta+2m3b2oh'!A23,"") -> 0 | H2: =IFERROR('dens_visc_beta+2m3b2oh'!B23,"") -> 0.82388 | I2: =IFERROR('dens_visc_beta+2m3b2oh'!G23,"") -> 0 | J2: =IFERROR('dens_visc_beta+2m3b2oh'!B37,"") -> 2.353 | K2: =IF(AND(ISNUMBER(H2),ISNUMBER(I2),ISNUMBER(J2)),"✓",COUNTIF(H2:J2,">-999")&"/3") -> ✓
A3: beta+2m3b2oh | B3: beta | C3: betaionone (trans) | D3: 2m3b2oh | E3: 2-methyl-3-buten-2-ol | F3: =IFERROR('dens_visc_beta+2m3b2oh'!B22,"") -> 20 | G3: =IFERROR('dens_visc_beta+2m3b2oh'!A24,"") -> 0.099609445 | H3: =IFERROR('dens_visc_beta+2m3b2oh'!B24,"") -> 0.84735 | I3: =IFERROR('dens_visc_beta+2m3b2oh'!G24,"") -> -0.27169592 | J3: =IFERROR('dens_visc_beta+2m3b2oh'!B38,"") -> 2.826 | K3: =IF(AND(ISNUMBER(H3),ISNUMBER(I3),ISNUMBER(J3)),"✓",COUNTIF(H3:J3,">-999")&"/3") -> ✓
A4: beta+2m3b2oh | B4: beta | C4: betaionone (trans) | D4: 2m3b2oh | E4: 2-methyl-3-buten-2-ol | F4: =IFERROR('dens_visc_beta+2m3b2oh'!B22,"") -> 20 | G4: =IFERROR('dens_visc_beta+2m3b2oh'!A25,"") -> 0.19728379 | H4: =IFERROR('dens_visc_beta+2m3b2oh'!B25,"") -> 0.86523 | I4: =IFERROR('dens_visc_beta+2m3b2oh'!G25,"") -> -0.31009368 | J4: =IFERROR('dens_visc_beta+2m3b2oh'!B39,"") -> 3.278 | K4: =IF(AND(ISNUMBER(H4),ISNUMBER(I4),ISNUMBER(J4)),"✓",COUNTIF(H4:J4,">-999")&"/3") -> ✓
A5: beta+2m3b2oh | B5: beta | C5: betaionone (trans) | D5: 2m3b2oh | E5: 2-methyl-3-buten-2-ol | F5: =IFERROR('dens_visc_beta+2m3b2oh'!B22,"") -> 20 | G5: =IFERROR('dens_visc_beta+2m3b2oh'!A26,"") -> 0.29604169 | H5: =IFERROR('dens_visc_beta+2m3b2oh'!B26,"") -> 0.88031 | I5: =IFERROR('dens_visc_beta+2m3b2oh'!G26,"") -> -0.29185239 | J5: =IFERROR('dens_visc_beta+2m3b2oh'!B40,"") -> 3.764 | K5: =IF(AND(ISNUMBER(H5),ISNUMBER(I5),ISNUMBER(J5)),"✓",COUNTIF(H5:J5,">-999")&"/3") -> ✓
A6: beta+2m3b2oh | B6: beta | C6: betaionone (trans) | D6: 2m3b2oh | E6: 2-methyl-3-buten-2-ol | F6: =IFERROR('dens_visc_beta+2m3b2oh'!B22,"") -> 20 | G6: =IFERROR('dens_visc_beta+2m3b2oh'!A27,"") -> 0.39641924 | H6: =IFERROR('dens_visc_beta+2m3b2oh'!B27,"") -> 0.89316 | I6: =IFERROR('dens_visc_beta+2m3b2oh'!G27,"") -> -0.2140936 | J6: =IFERROR('dens_visc_beta+2m3b2oh'!B41,"") -> 4.321 | K6: =IF(AND(ISNUMBER(H6),ISNUMBER(I6),ISNUMBER(J6)),"✓",COUNTIF(H6:J6,">-999")&"/3") -> ✓
A7: beta+2m3b2oh | B7: beta | C7: betaionone (trans) | D7: 2m3b2oh | E7: 2-methyl-3-buten-2-ol | F7: =IFERROR('dens_visc_beta+2m3b2oh'!B22,"") -> 20 | G7: =IFERROR('dens_visc_beta+2m3b2oh'!A28,"") -> 0.49244461 | H7: =IFERROR('dens_visc_beta+2m3b2oh'!B28,"") -> 0.90411 | I7: =IFERROR('dens_visc_beta+2m3b2oh'!G28,"") -> -0.17858269 | J7: =IFERROR('dens_visc_beta+2m3b2oh'!B42,"") -> 4.948 | K7: =IF(AND(ISNUMBER(H7),ISNUMBER(I7),ISNUMBER(J7)),"✓",COUNTIF(H7:J7,">-999")&"/3") -> ✓
A8: beta+2m3b2oh | B8: beta | C8: betaionone (trans) | D8: 2m3b2oh | E8: 2-methyl-3-buten-2-ol | F8: =IFERROR('dens_visc_beta+2m3b2oh'!B22,"") -> 20 | G8: =IFERROR('dens_visc_beta+2m3b2oh'!A29,"") -> 0.59529209 | H8: =IFERROR('dens_visc_beta+2m3b2oh'!B29,"") -> 0.91437 | I8: =IFERROR('dens_visc_beta+2m3b2oh'!G29,"") -> -0.13172741 | J8: =IFERROR('dens_visc_beta+2m3b2oh'!B43,"") -> 5.757 | K8: =IF(AND(ISNUMBER(H8),ISNUMBER(I8),ISNUMBER(J8)),"✓",COUNTIF(H8:J8,">-999")&"/3") -> ✓
A9: beta+2m3b2oh | B9: beta | C9: betaionone (trans) | D9: 2m3b2oh | E9: 2-methyl-3-buten-2-ol | F9: =IFERROR('dens_visc_beta+2m3b2oh'!B22,"") -> 20 | G9: =IFERROR('dens_visc_beta+2m3b2oh'!A30,"") -> 0.6940457 | H9: =IFERROR('dens_visc_beta+2m3b2oh'!B30,"") -> 0.92296 | I9: =IFERROR('dens_visc_beta+2m3b2oh'!G30,"") -> -0.063997305 | J9: =IFERROR('dens_visc_beta+2m3b2oh'!B44,"") -> 6.687 | K9: =IF(AND(ISNUMBER(H9),ISNUMBER(I9),ISNUMBER(J9)),"✓",COUNTIF(H9:J9,">-999")&"/3") -> ✓
A10: beta+2m3b2oh | B10: beta | C10: betaionone (trans) | D10: 2m3b2oh | E10: 2-methyl-3-buten-2-ol | F10: =IFERROR('dens_visc_beta+2m3b2oh'!B22,"") -> 20 | G10: =IFERROR('dens_visc_beta+2m3b2oh'!A31,"") -> 0.79734561 | H10: =IFERROR('dens_visc_beta+2m3b2oh'!B31,"") -> 0.93115 | I10: =IFERROR('dens_visc_beta+2m3b2oh'!G31,"") -> -0.030710249 | J10: =IFERROR('dens_visc_beta+2m3b2oh'!B45,"") -> 7.915 | K10: =IF(AND(ISNUMBER(H10),ISNUMBER(I10),ISNUMBER(J10)),"✓",COUNTIF(H10:J10,">-999")&"/3") -> ✓
A11: beta+2m3b2oh | B11: beta | C11: betaionone (trans) | D11: 2m3b2oh | E11: 2-methyl-3-buten-2-ol | F11: =IFERROR('dens_visc_beta+2m3b2oh'!B22,"") -> 20 | G11: =IFERROR('dens_visc_beta+2m3b2oh'!A32,"") -> 0.89719236 | H11: =IFERROR('dens_visc_beta+2m3b2oh'!B32,"") -> 0.93847 | I11: =IFERROR('dens_visc_beta+2m3b2oh'!G32,"") -> -0.045834283 | J11: =IFERROR('dens_visc_beta+2m3b2oh'!B46,"") -> 9.388 | K11: =IF(AND(ISNUMBER(H11),ISNUMBER(I11),ISNUMBER(J11)),"✓",COUNTIF(H11:J11,">-999")&"/3") -> ✓
A12: beta+2m3b2oh | B12: beta | C12: betaionone (trans) | D12: 2m3b2oh | E12: 2-methyl-3-buten-2-ol | F12: =IFERROR('dens_visc_beta+2m3b2oh'!B22,"") -> 20 | G12: =IFERROR('dens_visc_beta+2m3b2oh'!A33,"") -> 1 | H12: =IFERROR('dens_visc_beta+2m3b2oh'!B33,"") -> 0.94498 | I12: =IFERROR('dens_visc_beta+2m3b2oh'!G33,"") -> 0 | J12: =IFERROR('dens_visc_beta+2m3b2oh'!B47,"") -> 11.31 | K12: =IF(AND(ISNUMBER(H12),ISNUMBER(I12),ISNUMBER(J12)),"✓",COUNTIF(H12:J12,">-999")&"/3") -> ✓
A13: beta+2m3b2oh | B13: beta | C13: betaionone (trans) | D13: 2m3b2oh | E13: 2-methyl-3-buten-2-ol | F13: =IFERROR('dens_visc_beta+2m3b2oh'!C22,"") -> 30 | G13: =IFERROR('dens_visc_beta+2m3b2oh'!A23,"") -> 0 | H13: =IFERROR('dens_visc_beta+2m3b2oh'!C23,"") -> 0.81447 | I13: =IFERROR('dens_visc_beta+2m3b2oh'!H23,"") -> 0 | J13: =IFERROR('dens_visc_beta+2m3b2oh'!C37,"") -> 1.682 | K13: =IF(AND(ISNUMBER(H13),ISNUMBER(I13),ISNUMBER(J13)),"✓",COUNTIF(H13:J13,">-999")&"/3") -> ✓
A14: beta+2m3b2oh | B14: beta | C14: betaionone (trans) | D14: 2m3b2oh | E14: 2-methyl-3-buten-2-ol | F14: =IFERROR('dens_visc_beta+2m3b2oh'!C22,"") -> 30 | G14: =IFERROR('dens_visc_beta+2m3b2oh'!A24,"") -> 0.099609445 | H14: =IFERROR('dens_visc_beta+2m3b2oh'!C24,"") -> 0.83789 | I14: =IFERROR('dens_visc_beta+2m3b2oh'!H24,"") -> -0.23764907 | J14: =IFERROR('dens_visc_beta+2m3b2oh'!C38,"") -> 2.021 | K14: =IF(AND(ISNUMBER(H14),ISNUMBER(I14),ISNUMBER(J14)),"✓",COUNTIF(H14:J14,">-999")&"/3") -> ✓
A15: beta+2m3b2oh | B15: beta | C15: betaionone (trans) | D15: 2m3b2oh | E15: 2-methyl-3-buten-2-ol | F15: =IFERROR('dens_visc_beta+2m3b2oh'!C22,"") -> 30 | G15: =IFERROR('dens_visc_beta+2m3b2oh'!A25,"") -> 0.19728379 | H15: =IFERROR('dens_visc_beta+2m3b2oh'!C25,"") -> 0.85629 | I15: =IFERROR('dens_visc_beta+2m3b2oh'!H25,"") -> -0.31827546 | J15: =IFERROR('dens_visc_beta+2m3b2oh'!C39,"") -> 2.35 | K15: =IF(AND(ISNUMBER(H15),ISNUMBER(I15),ISNUMBER(J15)),"✓",COUNTIF(H15:J15,">-999")&"/3") -> ✓
A16: beta+2m3b2oh | B16: beta | C16: betaionone (trans) | D16: 2m3b2oh | E16: 2-methyl-3-buten-2-ol | F16: =IFERROR('dens_visc_beta+2m3b2oh'!C22,"") -> 30 | G16: =IFERROR('dens_visc_beta+2m3b2oh'!A26,"") -> 0.29604169 | H16: =IFERROR('dens_visc_beta+2m3b2oh'!C26,"") -> 0.87163 | I16: =IFERROR('dens_visc_beta+2m3b2oh'!H26,"") -> -0.30843872 | J16: =IFERROR('dens_visc_beta+2m3b2oh'!C40,"") -> 2.698 | K16: =IF(AND(ISNUMBER(H16),ISNUMBER(I16),ISNUMBER(J16)),"✓",COUNTIF(H16:J16,">-999")&"/3") -> ✓
A17: beta+2m3b2oh | B17: beta | C17: betaionone (trans) | D17: 2m3b2oh | E17: 2-methyl-3-buten-2-ol | F17: =IFERROR('dens_visc_beta+2m3b2oh'!C22,"") -> 30 | G17: =IFERROR('dens_visc_beta+2m3b2oh'!A27,"") -> 0.39641924 | H17: =IFERROR('dens_visc_beta+2m3b2oh'!C27,"") -> 0.8848 | I17: =IFERROR('dens_visc_beta+2m3b2oh'!H27,"") -> -0.25119815 | J17: =IFERROR('dens_visc_beta+2m3b2oh'!C41,"") -> 3.087 | K17: =IF(AND(ISNUMBER(H17),ISNUMBER(I17),ISNUMBER(J17)),"✓",COUNTIF(H17:J17,">-999")&"/3") -> ✓
A18: beta+2m3b2oh | B18: beta | C18: betaionone (trans) | D18: 2m3b2oh | E18: 2-methyl-3-buten-2-ol | F18: =IFERROR('dens_visc_beta+2m3b2oh'!C22,"") -> 30 | G18: =IFERROR('dens_visc_beta+2m3b2oh'!A28,"") -> 0.49244461 | H18: =IFERROR('dens_visc_beta+2m3b2oh'!C28,"") -> 0.89579 | I18: =IFERROR('dens_visc_beta+2m3b2oh'!H28,"") -> -0.19512472 | J18: =IFERROR('dens_visc_beta+2m3b2oh'!C42,"") -> 3.51 | K18: =IF(AND(ISNUMBER(H18),ISNUMBER(I18),ISNUMBER(J18)),"✓",COUNTIF(H18:J18,">-999")&"/3") -> ✓
A19: beta+2m3b2oh | B19: beta | C19: betaionone (trans) | D19: 2m3b2oh | E19: 2-methyl-3-buten-2-ol | F19: =IFERROR('dens_visc_beta+2m3b2oh'!C22,"") -> 30 | G19: =IFERROR('dens_visc_beta+2m3b2oh'!A29,"") -> 0.59529209 | H19: =IFERROR('dens_visc_beta+2m3b2oh'!C29,"") -> 0.90623 | I19: =IFERROR('dens_visc_beta+2m3b2oh'!H29,"") -> -0.15138912 | J19: =IFERROR('dens_visc_beta+2m3b2oh'!C43,"") -> 4.038 | K19: =IF(AND(ISNUMBER(H19),ISNUMBER(I19),ISNUMBER(J19)),"✓",COUNTIF(H19:J19,">-999")&"/3") -> ✓
A20: beta+2m3b2oh | B20: beta | C20: betaionone (trans) | D20: 2m3b2oh | E20: 2-methyl-3-buten-2-ol | F20: =IFERROR('dens_visc_beta+2m3b2oh'!C22,"") -> 30 | G20: =IFERROR('dens_visc_beta+2m3b2oh'!A30,"") -> 0.6940457 | H20: =IFERROR('dens_visc_beta+2m3b2oh'!C30,"") -> 0.91494 | I20: =IFERROR('dens_visc_beta+2m3b2oh'!H30,"") -> -0.079040884 | J20: =IFERROR('dens_visc_beta+2m3b2oh'!C44,"") -> 4.636 | K20: =IF(AND(ISNUMBER(H20),ISNUMBER(I20),ISNUMBER(J20)),"✓",COUNTIF(H20:J20,">-999")&"/3") -> ✓
A21: beta+2m3b2oh | B21: beta | C21: betaionone (trans) | D21: 2m3b2oh | E21: 2-methyl-3-buten-2-ol | F21: =IFERROR('dens_visc_beta+2m3b2oh'!C22,"") -> 30 | G21: =IFERROR('dens_visc_beta+2m3b2oh'!A31,"") -> 0.79734561 | H21: =IFERROR('dens_visc_beta+2m3b2oh'!C31,"") -> 0.92328 | I21: =IFERROR('dens_visc_beta+2m3b2oh'!H31,"") -> -0.048558676 | J21: =IFERROR('dens_visc_beta+2m3b2oh'!C45,"") -> 5.372 | K21: =IF(AND(ISNUMBER(H21),ISNUMBER(I21),ISNUMBER(J21)),"✓",COUNTIF(H21:J21,">-999")&"/3") -> ✓
A22: beta+2m3b2oh | B22: beta | C22: betaionone (trans) | D22: 2m3b2oh | E22: 2-methyl-3-buten-2-ol | F22: =IFERROR('dens_visc_beta+2m3b2oh'!C22,"") -> 30 | G22: =IFERROR('dens_visc_beta+2m3b2oh'!A32,"") -> 0.89719236 | H22: =IFERROR('dens_visc_beta+2m3b2oh'!C32,"") -> 0.93065 | I22: =IFERROR('dens_visc_beta+2m3b2oh'!H32,"") -> -0.04978414 | J22: =IFERROR('dens_visc_beta+2m3b2oh'!C46,"") -> 6.239 | K22: =IF(AND(ISNUMBER(H22),ISNUMBER(I22),ISNUMBER(J22)),"✓",COUNTIF(H22:J22,">-999")&"/3") -> ✓
A23: beta+2m3b2oh | B23: beta | C23: betaionone (trans) | D23: 2m3b2oh | E23: 2-methyl-3-buten-2-ol | F23: =IFERROR('dens_visc_beta+2m3b2oh'!C22,"") -> 30 | G23: =IFERROR('dens_visc_beta+2m3b2oh'!A33,"") -> 1 | H23: =IFERROR('dens_visc_beta+2m3b2oh'!C33,"") -> 0.93726 | I23: =IFERROR('dens_visc_beta+2m3b2oh'!H33,"") -> 0 | J23: =IFERROR('dens_visc_beta+2m3b2oh'!C47,"") -> 7.323 | K23: =IF(AND(ISNUMBER(H23),ISNUMBER(I23),ISNUMBER(J23)),"✓",COUNTIF(H23:J23,">-999")&"/3") -> ✓
A24: beta+2m3b2oh | B24: beta | C24: betaionone (trans) | D24: 2m3b2oh | E24: 2-methyl-3-buten-2-ol | F24: =IFERROR('dens_visc_beta+2m3b2oh'!D22,"") -> 40 | G24: =IFERROR('dens_visc_beta+2m3b2oh'!A23,"") -> 0 | H24: =IFERROR('dens_visc_beta+2m3b2oh'!D23,"") -> 0.8047 | I24: =IFERROR('dens_visc_beta+2m3b2oh'!I23,"") -> 0 | J24: =IFERROR('dens_visc_beta+2m3b2oh'!D37,"") -> 1.247 | K24: =IF(AND(ISNUMBER(H24),ISNUMBER(I24),ISNUMBER(J24)),"✓",COUNTIF(H24:J24,">-999")&"/3") -> ✓
A25: beta+2m3b2oh | B25: beta | C25: betaionone (trans) | D25: 2m3b2oh | E25: 2-methyl-3-buten-2-ol | F25: =IFERROR('dens_visc_beta+2m3b2oh'!D22,"") -> 40 | G25: =IFERROR('dens_visc_beta+2m3b2oh'!A24,"") -> 0.099609445 | H25: =IFERROR('dens_visc_beta+2m3b2oh'!D24,"") -> 0.8284 | I25: =IFERROR('dens_visc_beta+2m3b2oh'!I24,"") -> -0.24212496 | J25: =IFERROR('dens_visc_beta+2m3b2oh'!D38,"") -> 1.502 | K25: =IF(AND(ISNUMBER(H25),ISNUMBER(I25),ISNUMBER(J25)),"✓",COUNTIF(H25:J25,">-999")&"/3") -> ✓
A26: beta+2m3b2oh | B26: beta | C26: betaionone (trans) | D26: 2m3b2oh | E26: 2-methyl-3-buten-2-ol | F26: =IFERROR('dens_visc_beta+2m3b2oh'!D22,"") -> 40 | G26: =IFERROR('dens_visc_beta+2m3b2oh'!A25,"") -> 0.19728379 | H26: =IFERROR('dens_visc_beta+2m3b2oh'!D25,"") -> 0.84711 | I26: =IFERROR('dens_visc_beta+2m3b2oh'!I25,"") -> -0.33172661 | J26: =IFERROR('dens_visc_beta+2m3b2oh'!D39,"") -> 1.753 | K26: =IF(AND(ISNUMBER(H26),ISNUMBER(I26),ISNUMBER(J26)),"✓",COUNTIF(H26:J26,">-999")&"/3") -> ✓
A27: beta+2m3b2oh | B27: beta | C27: betaionone (trans) | D27: 2m3b2oh | E27: 2-methyl-3-buten-2-ol | F27: =IFERROR('dens_visc_beta+2m3b2oh'!D22,"") -> 40 | G27: =IFERROR('dens_visc_beta+2m3b2oh'!A26,"") -> 0.29604169 | H27: =IFERROR('dens_visc_beta+2m3b2oh'!D26,"") -> 0.86274 | I27: =IFERROR('dens_visc_beta+2m3b2oh'!I26,"") -> -0.3295592 | J27: =IFERROR('dens_visc_beta+2m3b2oh'!D40,"") -> 2.016 | K27: =IF(AND(ISNUMBER(H27),ISNUMBER(I27),ISNUMBER(J27)),"✓",COUNTIF(H27:J27,">-999")&"/3") -> ✓
A28: beta+2m3b2oh | B28: beta | C28: betaionone (trans) | D28: 2m3b2oh | E28: 2-methyl-3-buten-2-ol | F28: =IFERROR('dens_visc_beta+2m3b2oh'!D22,"") -> 40 | G28: =IFERROR('dens_visc_beta+2m3b2oh'!A27,"") -> 0.39641924 | H28: =IFERROR('dens_visc_beta+2m3b2oh'!D27,"") -> 0.87617 | I28: =IFERROR('dens_visc_beta+2m3b2oh'!I27,"") -> -0.27784243 | J28: =IFERROR('dens_visc_beta+2m3b2oh'!D41,"") -> 2.304 | K28: =IF(AND(ISNUMBER(H28),ISNUMBER(I28),ISNUMBER(J28)),"✓",COUNTIF(H28:J28,">-999")&"/3") -> ✓
A29: beta+2m3b2oh | B29: beta | C29: betaionone (trans) | D29: 2m3b2oh | E29: 2-methyl-3-buten-2-ol | F29: =IFERROR('dens_visc_beta+2m3b2oh'!D22,"") -> 40 | G29: =IFERROR('dens_visc_beta+2m3b2oh'!A28,"") -> 0.49244461 | H29: =IFERROR('dens_visc_beta+2m3b2oh'!D28,"") -> 0.88735 | I29: =IFERROR('dens_visc_beta+2m3b2oh'!I28,"") -> -0.22063289 | J29: =IFERROR('dens_visc_beta+2m3b2oh'!D42,"") -> 2.61 | K29: =IF(AND(ISNUMBER(H29),ISNUMBER(I29),ISNUMBER(J29)),"✓",COUNTIF(H29:J29,">-999")&"/3") -> ✓
A30: beta+2m3b2oh | B30: beta | C30: betaionone (trans) | D30: 2m3b2oh | E30: 2-methyl-3-buten-2-ol | F30: =IFERROR('dens_visc_beta+2m3b2oh'!D22,"") -> 40 | G30: =IFERROR('dens_visc_beta+2m3b2oh'!A29,"") -> 0.59529209 | H30: =IFERROR('dens_visc_beta+2m3b2oh'!D29,"") -> 0.89798 | I30: =IFERROR('dens_visc_beta+2m3b2oh'!I29,"") -> -0.17676126 | J30: =IFERROR('dens_visc_beta+2m3b2oh'!D43,"") -> 2.986 | K30: =IF(AND(ISNUMBER(H30),ISNUMBER(I30),ISNUMBER(J30)),"✓",COUNTIF(H30:J30,">-999")&"/3") -> ✓
A31: beta+2m3b2oh | B31: beta | C31: betaionone (trans) | D31: 2m3b2oh | E31: 2-methyl-3-buten-2-ol | F31: =IFERROR('dens_visc_beta+2m3b2oh'!D22,"") -> 40 | G31: =IFERROR('dens_visc_beta+2m3b2oh'!A30,"") -> 0.6940457 | H31: =IFERROR('dens_visc_beta+2m3b2oh'!D30,"") -> 0.90684 | I31: =IFERROR('dens_visc_beta+2m3b2oh'!I30,"") -> -0.10047876 | J31: =IFERROR('dens_visc_beta+2m3b2oh'!D44,"") -> 3.396 | K31: =IF(AND(ISNUMBER(H31),ISNUMBER(I31),ISNUMBER(J31)),"✓",COUNTIF(H31:J31,">-999")&"/3") -> ✓
A32: beta+2m3b2oh | B32: beta | C32: betaionone (trans) | D32: 2m3b2oh | E32: 2-methyl-3-buten-2-ol | F32: =IFERROR('dens_visc_beta+2m3b2oh'!D22,"") -> 40 | G32: =IFERROR('dens_visc_beta+2m3b2oh'!A31,"") -> 0.79734561 | H32: =IFERROR('dens_visc_beta+2m3b2oh'!D31,"") -> 0.91532 | I32: =IFERROR('dens_visc_beta+2m3b2oh'!I31,"") -> -0.065900426 | J32: =IFERROR('dens_visc_beta+2m3b2oh'!D45,"") -> 3.883 | K32: =IF(AND(ISNUMBER(H32),ISNUMBER(I32),ISNUMBER(J32)),"✓",COUNTIF(H32:J32,">-999")&"/3") -> ✓
A33: beta+2m3b2oh | B33: beta | C33: betaionone (trans) | D33: 2m3b2oh | E33: 2-methyl-3-buten-2-ol | F33: =IFERROR('dens_visc_beta+2m3b2oh'!D22,"") -> 40 | G33: =IFERROR('dens_visc_beta+2m3b2oh'!A32,"") -> 0.89719236 | H33: =IFERROR('dens_visc_beta+2m3b2oh'!D32,"") -> 0.92277 | I33: =IFERROR('dens_visc_beta+2m3b2oh'!I32,"") -> -0.054219614 | J33: =IFERROR('dens_visc_beta+2m3b2oh'!D46,"") -> 4.443 | K33: =IF(AND(ISNUMBER(H33),ISNUMBER(I33),ISNUMBER(J33)),"✓",COUNTIF(H33:J33,">-999")&"/3") -> ✓
A34: beta+2m3b2oh | B34: beta | C34: betaionone (trans) | D34: 2m3b2oh | E34: 2-methyl-3-buten-2-ol | F34: =IFERROR('dens_visc_beta+2m3b2oh'!D22,"") -> 40 | G34: =IFERROR('dens_visc_beta+2m3b2oh'!A33,"") -> 1 | H34: =IFERROR('dens_visc_beta+2m3b2oh'!D33,"") -> 0.9295 | I34: =IFERROR('dens_visc_beta+2m3b2oh'!I33,"") -> 0 | J34: =IFERROR('dens_visc_beta+2m3b2oh'!D47,"") -> 5.121 | K34: =IF(AND(ISNUMBER(H34),ISNUMBER(I34),ISNUMBER(J34)),"✓",COUNTIF(H34:J34,">-999")&"/3") -> ✓
A35: beta+2m3b2oh | B35: beta | C35: betaionone (trans) | D35: 2m3b2oh | E35: 2-methyl-3-buten-2-ol | F35: =IFERROR('dens_visc_beta+2m3b2oh'!E22,"") -> 50 | G35: =IFERROR('dens_visc_beta+2m3b2oh'!A23,"") -> 0 | H35: =IFERROR('dens_visc_beta+2m3b2oh'!E23,"") -> 0.79458 | I35: =IFERROR('dens_visc_beta+2m3b2oh'!J23,"") -> 0 | J35: =IFERROR('dens_visc_beta+2m3b2oh'!E37,"") -> 0.964 | K35: =IF(AND(ISNUMBER(H35),ISNUMBER(I35),ISNUMBER(J35)),"✓",COUNTIF(H35:J35,">-999")&"/3") -> ✓
A36: beta+2m3b2oh | B36: beta | C36: betaionone (trans) | D36: 2m3b2oh | E36: 2-methyl-3-buten-2-ol | F36: =IFERROR('dens_visc_beta+2m3b2oh'!E22,"") -> 50 | G36: =IFERROR('dens_visc_beta+2m3b2oh'!A24,"") -> 0.099609445 | H36: =IFERROR('dens_visc_beta+2m3b2oh'!E24,"") -> 0.81866 | I36: =IFERROR('dens_visc_beta+2m3b2oh'!J24,"") -> -0.2546065 | J36: =IFERROR('dens_visc_beta+2m3b2oh'!E38,"") -> 1.154 | K36: =IF(AND(ISNUMBER(H36),ISNUMBER(I36),ISNUMBER(J36)),"✓",COUNTIF(H36:J36,">-999")&"/3") -> ✓
A37: beta+2m3b2oh | B37: beta | C37: betaionone (trans) | D37: 2m3b2oh | E37: 2-methyl-3-buten-2-ol | F37: =IFERROR('dens_visc_beta+2m3b2oh'!E22,"") -> 50 | G37: =IFERROR('dens_visc_beta+2m3b2oh'!A25,"") -> 0.19728379 | H37: =IFERROR('dens_visc_beta+2m3b2oh'!E25,"") -> 0.83774 | I37: =IFERROR('dens_visc_beta+2m3b2oh'!J25,"") -> -0.35673114 | J37: =IFERROR('dens_visc_beta+2m3b2oh'!E39,"") -> 1.352 | K37: =IF(AND(ISNUMBER(H37),ISNUMBER(I37),ISNUMBER(J37)),"✓",COUNTIF(H37:J37,">-999")&"/3") -> ✓
A38: beta+2m3b2oh | B38: beta | C38: betaionone (trans) | D38: 2m3b2oh | E38: 2-methyl-3-buten-2-ol | F38: =IFERROR('dens_visc_beta+2m3b2oh'!E22,"") -> 50 | G38: =IFERROR('dens_visc_beta+2m3b2oh'!A26,"") -> 0.29604169 | H38: =IFERROR('dens_visc_beta+2m3b2oh'!E26,"") -> 0.8537 | I38: =IFERROR('dens_visc_beta+2m3b2oh'!J26,"") -> -0.36324014 | J38: =IFERROR('dens_visc_beta+2m3b2oh'!E40,"") -> 1.56 | K38: =IF(AND(ISNUMBER(H38),ISNUMBER(I38),ISNUMBER(J38)),"✓",COUNTIF(H38:J38,">-999")&"/3") -> ✓
A39: beta+2m3b2oh | B39: beta | C39: betaionone (trans) | D39: 2m3b2oh | E39: 2-methyl-3-buten-2-ol | F39: =IFERROR('dens_visc_beta+2m3b2oh'!E22,"") -> 50 | G39: =IFERROR('dens_visc_beta+2m3b2oh'!A27,"") -> 0.39641924 | H39: =IFERROR('dens_visc_beta+2m3b2oh'!E27,"") -> 0.86742 | I39: =IFERROR('dens_visc_beta+2m3b2oh'!J27,"") -> -0.31672659 | J39: =IFERROR('dens_visc_beta+2m3b2oh'!E41,"") -> 1.783 | K39: =IF(AND(ISNUMBER(H39),ISNUMBER(I39),ISNUMBER(J39)),"✓",COUNTIF(H39:J39,">-999")&"/3") -> ✓
A40: beta+2m3b2oh | B40: beta | C40: betaionone (trans) | D40: 2m3b2oh | E40: 2-methyl-3-buten-2-ol | F40: =IFERROR('dens_visc_beta+2m3b2oh'!E22,"") -> 50 | G40: =IFERROR('dens_visc_beta+2m3b2oh'!A28,"") -> 0.49244461 | H40: =IFERROR('dens_visc_beta+2m3b2oh'!E28,"") -> 0.87883 | I40: =IFERROR('dens_visc_beta+2m3b2oh'!J28,"") -> -0.26025369 | J40: =IFERROR('dens_visc_beta+2m3b2oh'!E42,"") -> 2.016 | K40: =IF(AND(ISNUMBER(H40),ISNUMBER(I40),ISNUMBER(J40)),"✓",COUNTIF(H40:J40,">-999")&"/3") -> ✓
...

Sheet Componentes
A1: IDENTIFICADOR | G1: INVENTARIO | M1: PROPIEDADES | S1: SEGURIDAD | V1: METADATA
A2: ID | B2: Chemical Name | C2: Common Name(s) | D2: CAS Number | E2: Formula | F2: Canonical SMILES | G2: Location | H2: Supplier | I2: Grade/Purity | J2: Lot Number | K2: Quantity | L2: Unit | M2: MW | N2: Tb | O2: Tm | P2: ρ (25°C) | Q2: η (25°C) | R2: Pᵛᵃᵖ (25°C) | S2: Flash Point | T2: Hazard Class | U2: Storage | V2: Date Received | W2: Status | X2: Notes | AA2: comp_id | AB2: MW | AC2: purity
A3: Internal component code | B3: IUPAC or standard name | C3: Alternative names | D3: CAS registry number | E3: Molecular formula | F3: For modeling/databases | G3: Lab position (e.g., 3.1) | H3: Vendor name | I3: (Según batch) | J3: Batch identifier | K3: Amount available | L3: mL, g, kg, etc. | M3: g/mol | N3: °C (1 atm) | O3: °C | P3: g/cm³ | Q3: mPa·s | R3: kPa | S3: °C | T3: GHS classification | U3: Requirements | V3: YYYY-MM-DD | W3: Active/Depleted | X3: Additional info | AA3: beta | AB3: 192.3 | AC3: 0.978
A4: beta | B4: b-ionone (trans) | C4: - | D4: 14901-07-6 | E4: C13H20O | F4: CC1=C(C(CCC1)(C)C)/C=C/C(=O)C | G4: REFRIGERADOR | H4: Sigma-Aldrich | I4: 97.8% (GC) | J4: SHBL2869 | K4: 1 | L4: L | M4: 192.3 | N4: 266 | O4: - | P4: 0.942 | R4: - | S4: - | T4: - | U4: - | V4: - | W4: Active | AA4: 2pe | AB4: 122.16 | AC4: 1
A5: 2pe | B5: 2-phenylethanol | C5: - | D5: 60-12-8 | E5: C8H10O | F5: OCCc1ccccc1 | G5: 3.x | H5: Sigma-Aldrich | I5: > 99.9% (GC) | J5: SDBB2371 | K5: 1 | L5: L | M5: 122.16 | N5: 219 | O5: - | P5: 1.02 | R5: - | S5: - | T5: - | U5: - | V5: - | W5: Active | AA5: gamma | AB5: 170.25 | AC5: 0.987
A6: gamma | B6: g-decalactone | C6: - | D6: 706-14-9 | E6: C10H18O2 | F6: CCCCCCC1CCC(=O)O1 | G6: 3.x | H6: Sigma-Aldrich | I6: 98.7% (GC) | J6: SHBR4960 | K6: 1 | L6: L | M6: 170.25 | N6: 285 | O6: - | P6: 0.969 | R6: - | S6: - | T6: - | U6: - | V6: - | W6: Active | AA6: 2m3b2oh | AB6: 86.13 | AC6: 0.996
A7: 2m3b2oh | B7: 2-methyl-3-buten-2-ol | C7: 2M3B2OH | D7: 115-18-4 | E7: C5H10O | F7: CC(C)(C=C)O | G7: REFRIGERADOR | H7: Aldrich | I7: 99.6% (GC) | J7: STBH5331 | K7: 1 | L7: L | M7: 86.13 | N7: 99 | O7: - | P7: 0.824 | R7: - | S7: - | T7: - | U7: - | V7: - | W7: Active | AA7: 2m2boh | AB7: 88.15 | AC7: 1
A8: 2m2boh | B8: 2-methyl-2-butanol | C8: tert-amyl alcohol | D8: 75-85-4 | E8: C5H12O | F8: CCC(C)(C)O | G8: 3.2 | H8: Sigma-Aldrich | I8: >99.9% (GC) | J8: SDBB4598 | K8: 1 | L8: L | M8: 88.15 | N8: 102 | O8: - | P8: 0.805 | R8: - | S8: - | T8: - | U8: - | V8: - | W8: Active | AA8: hexoh | AB8: 102.17 | AC8: 0.998
A9: hexoh | B9: 1-hexanol | C9: - | D9: 111-27-3 | E9: C6H18O | F9: CCCCCCO | G9: 1.3. | H9: Sigma-Aldrich | I9: 99.8% (GC) | J9: SHBC9189V | K9: 700 | L9: mL | M9: 102.17 | N9: 156 | O9: - | P9: 0.814 | R9: - | S9: - | T9: - | U9: - | V9: - | W9: Active | AA9: octoh | AB9: 130.23 | AC9: 0.997
A10: octoh | B10: 1-octanol | C10: - | D10: 111-87-5 | E10: C8H18O | F10: CCCCCCCCO | G10: 1.2 | H10: Sigma-Aldrich | I10: 99.7% (GC) | J10: SDBB1117 | K10: 200? | L10: mL | M10: 130.23 | N10: 195 | O10: - | P10: 0.824 | R10: - | S10: - | T10: - | U10: - | V10: - | W10: Active | AA10: mibk | AB10: 100.16 | AC10: 0.998
A11: mibk | B11: methyl isobutyl ketone | C11: MIBK | D11: 108-10-1 | E11: C6H12O | F11: CC(C)CC(=O)C | G11: 2.4 | H11: Merck Millipor | I11: 99.8% (GC) | J11: K51239346927 | K11: 300? | L11: mL | M11: 100.16 | N11: 115 | O11: - | P11: 0.802 | R11: - | S11: - | T11: - | U11: - | V11: - | W11: Active | AA11: 2octanone | AB11: 128.21 | AC11: 0.988
A12: 2octanone | B12: 2-octanone | C12: Hexyl methyl ketone | D12: 111-13-7 | E12: C8H16O | F12: CCCCCCC(=O)C | G12: 3.2 | H12: Sigma-Aldrich | I12: 98.8% (GC) | J12: SHBQ4121 | K12: 200? | L12: mL | M12: 128.21 | N12: 173 | O12: - | P12: 0.819 | R12: - | S12: - | T12: - | U12: - | V12: - | W12: Active
A13: thymol | B13: Thymol | C13: - | D13: 89-83-8 | E13: C10H14O | F13: Cc1ccc(C(C)C)c(O)c1 | G13: 1.2 | H13: Sigma-Aldrich | I13: >99.9% (GC) | J13: SHBQ5769 | K13: 800 | L13: g | M13: 150.22 | N13: 233 | O13: - | P13: 0.96 | R13: - | S13: - | T13: - | U13: - | V13: - | W13: Active
A14: carvone | B14: L-Carvone | C14: (-)-Carvone | D14: 6485-40-1 | E14: C10H14O | F14: C=C(C)[C@@H]1CC=C(C)C(=O)C1 | G14: 1.2 | H14: Sigma-Aldrich | I14: 99.2% (GC) | J14: SHBQ8402 | K14: 1 | L14: kg | M14: 150.22 | N14: 226 | O14: - | P14: 0.96 | R14: - | S14: - | T14: - | U14: - | V14: - | W14: Active
A15: camphor | B15: DL-Camphor | C15: - | D15: 76-22-2 | E15: C10H16O | F15: CC1(C)C2CCC1(C)C(=O)C2 | G15: 3.2 | H15: Sigma-Aldrich | I15: 96.9% (GC) | J15: SDBB0718 | K15: 250 | L15: g | M15: 152.24 | N15: 210 | O15: - | P15: 0.99 | R15: - | S15: - | T15: - | U15: - | V15: - | W15: Active
A16: geraniol | B16: Geraniol | C16: - | D16: 106-24-1 | E16: C10H18O | F16: CC(C)=CCC/C(C)=C/CO | G16: 2.3 | H16: Sigma-Aldrich | I16: 98.9% (GC) | J16: SHBP7700 | K16: 700 | L16: g | M16: 154.25 | N16: 229 | O16: - | P16: 0.889 | R16: - | S16: - | T16: - | U16: - | V16: - | W16: Active
A17: carvacrol | B17: Carvacrol | C17: - | D17: 499-75-2 | E17: C10H14O | F17: Cc1ccc(C(C)C)cc1O | G17: 2.1 | H17: Sigma-Aldrich | I17: 99.7% (GC) | J17: SHBQ9085 | K17: 400? | L17: mL | M17: 150.22 | N17: 239 | O17: - | P17: 0.977 | R17: - | S17: - | T17: - | U17: - | V17: - | W17: Active
A18: eugenol | B18: Eugenol | C18: - | D18: 97-53-0 | E18: C10H12O2 | F18: C=CCc1ccc(O)c(OC)c1 | G18: 1.3 | H18: Sigma-Aldrich | I18: 99.2% (GC) | J18: SHBM4053 | K18: 500? | L18: mL | M18: 164.2 | N18: 215 | O18: - | P18: 1.06 | R18: - | S18: - | T18: - | U18: - | V18: - | W18: Active
A19: h2o | B19: Water | C19: - | D19: - | E19: - | G19: - | H19: - | I19: HPLC | J19: - | K19: - | L19: - | M19: 18.02 | N19: 100 | O19: - | R19: - | S19: - | T19: - | U19: - | V19: - | W19: Active
B21: Aroma (soluto)
B22: Solventes
B23: DESs
B24: Agua (diluyente)

Sheet datos_solventes
B2: Densidad | C2: 2-methyl-3-buten-2-ol | D2: 2-methyl-2-butanol | E2: 1-hexanol | F2: 1-octanol | G2: methyl isobutyl ketone | H2: 2-octanone
B3: b-ionona
B4: 2-phenylethanol
B5: g-decalactone
B7: Viscosidad | C7: 2-methyl-3-buten-2-ol | D7: 2-methyl-2-butanol | E7: 1-hexanol | F7: 1-octanol | G7: methyl isobutyl ketone | H7: 2-octanone
B8: b-ionona
B9: 2-phenylethanol
B10: g-decalactone
B12: LLE con agua | C12: 2-methyl-3-buten-2-ol | D12: 2-methyl-2-butanol | E12: 1-hexanol | F12: 1-octanol | G12: methyl isobutyl ketone | H12: 2-octanone
B13: b-ionona
B14: 2-phenylethanol
B15: g-decalactone
B17: VLE | C17: 2-methyl-3-buten-2-ol | D17: 2-methyl-2-butanol | E17: 1-hexanol | F17: 1-octanol | G17: methyl isobutyl ketone | H17: 2-octanone
B18: b-ionona
B19: 2-phenylethanol
B20: g-decalactone
C22: Published
C23: Measured
C24: Falta Fleck | E24: Meter al viscosimetro
C25: Falta Vanesa
C26: Falta Hector

Sheet datos_des
B2: Densidad | C2: ThyCar | D2: ThyGer | E2: ThyCarvon | F2: ThyEug | G2: CamCar | H2: CamGer | I2: CamCarvac | J2: CamEug
B3: b-ionona | L3: HBA | M3: HBD
B4: 2-phenylethanol | K4: 1 | L4: Thymol | M4: Carvone | N4: 1
B5: g-decalactone | K5: 2 | L5: Camphor | M5: Geraniol | N5: 2
M6: Carvacrol | N6: 3
B7: Viscosidad | C7: ThyCar | D7: ThyGer | E7: ThyCarvon | F7: ThyEug | G7: CamCar | H7: CamGer | I7: CamCarvac | J7: CamEug | M7: Eugenol | N7: 4
B8: b-ionona
B9: 2-phenylethanol
B10: g-decalactone
B12: LLE con agua | C12: ThyCar | D12: ThyGer | E12: ThyCarvon | F12: ThyEug | G12: CamCar | H12: CamGer | I12: CamCarvac | J12: CamEug
B13: b-ionona
B14: 2-phenylethanol
B15: g-decalactone
B17: VLE | C17: ThyCar | D17: ThyGer | E17: ThyCarvon | F17: ThyEug | G17: CamCar | H17: CamGer | I17: CamCarvac | J17: CamEug
B18: b-ionona
B19: 2-phenylethanol
B20: g-decalactone
C23: Falta fleck

Sheet densidad_viscosidad_puros
A1: 2-methyl-3-buten-2-ol
A2: // DATOS DE DENSIDAD Y VISCOSIDAD IMPORTADOS
B3: Lovis / DMA
A4: temperature_c | B4: Unique Sample Id | C4: Date | D4: Time | E4: Sample Name | F4: Master Condition | G4: Density | H4: Density Temperature | I4: Lovis Dyn. Viscosity | J4: Lovis Kin. Viscosity | K4: Lovis Temperature | L4: Lovis Variation Coefficient | M4: Lovis Fw/Bw Deviation | N4: Lovis Current Capillary
A5: 20 | B5: 12817 | C5: 19-11-2025 | D5: 0 | E5: 2-methyl-3-buten-2-ol_pure | F5: valid | G5: 0.82388 | H5: 20.02 | I5: 2.353 | J5: 2.856 | K5: 20 | L5: 0.02 | M5: 0.12 | N5: Chico (35990024)
A6: 30 | B6: 12818 | C6: 19-11-2025 | D6: 0.41909722 | E6: 2-methyl-3-buten-2-ol_pure | F6: valid | G6: 0.81447 | H6: 29.98 | I6: 1.682 | J6: 2.065 | K6: 30 | L6: 0.02 | M6: 0.74 | N6: Chico (35990024)
A7: 40 | B7: 12819 | C7: 19-11-2025 | D7: 0.42425926 | E7: 2-methyl-3-buten-2-ol_pure | F7: valid | G7: 0.8047 | H7: 39.97 | I7: 1.247 | J7: 1.549 | K7: 40 | L7: 0.08 | M7: 0.83 | N7: Chico (35990024)
A8: 50 | B8: 12820 | C8: 19-11-2025 | D8: 0.43135417 | E8: 2-methyl-3-buten-2-ol_pure | F8: valid | G8: 0.79458 | H8: 49.97 | I8: 0.964 | J8: 1.214 | K8: 50 | L8: 0.04 | M8: 1 | N8: Chico (35990024)
A9: 60 | B9: 12821 | C9: 19-11-2025 | D9: 0.44179398 | E9: 2-methyl-3-buten-2-ol_pure | F9: valid | G9: 0.7841 | H9: 59.98 | I9: 0.757 | J9: 0.965 | K9: 60 | L9: 0.05 | M9: 0.17 | N9: Chico (35990024)
I10: =(I6-I5) / 10 -> -0.0671
A11: 2-methyl-2-butanol
A12: // DATOS DE DENSIDAD Y VISCOSIDAD IMPORTADOS
B13: Lovis / DMA
A14: temperature_c | B14: Unique Sample Id | C14: Date | D14: Time | E14: Sample Name | F14: Master Condition | G14: Density | H14: Density Temperature | I14: Lovis Dyn. Viscosity | J14: Lovis Kin. Viscosity | K14: Lovis Temperature | L14: Lovis Variation Coefficient | M14: Lovis Fw/Bw Deviation | N14: Lovis Current Capillary
A15: 20 | B15: 12797 | C15: 18-11-2025 | D15: 0.78501157 | E15: 2-methyl-2-butanol_pure | F15: valid | G15: 0.80899 | H15: 20.06 | I15: 4.244 | J15: 5.245 | K15: 20 | L15: 0.06 | M15: 0.22 | N15: Chico (35990024)
A16: 30 | B16: 12798 | C16: 18-11-2025 | D16: 0.7918287 | E16: 2-methyl-2-butanol_pure | F16: valid | G16: 0.79979 | H16: 29.97 | I16: 2.776 | J16: 3.471 | K16: 30 | L16: 0.06 | M16: 0.88 | N16: Chico (35990024)
A17: 40 | B17: 12799 | C17: 18-11-2025 | D17: 0.79924769 | E17: 2-methyl-2-butanol_pure | F17: valid | G17: 0.79035 | H17: 39.97 | I17: 1.918 | J17: 2.427 | K17: 40 | L17: 0.08 | M17: 0.94 | N17: Chico (35990024)
A18: 50 | B18: 12800 | C18: 18-11-2025 | D18: 0.80935185 | E18: 2-methyl-2-butanol_pure | F18: valid | G18: 0.7806 | H18: 49.98 | I18: 1.397 | J18: 1.789 | K18: 50 | L18: 0.12 | M18: 1.12 | N18: Chico (35990024)
A19: 60 | B19: 12802 | C19: 18-11-2025 | D19: 0.83018519 | E19: 2-methyl-2-butanol_pure | F19: valid | G19: 0.77049 | H19: 59.98 | I19: 1.036 | J19: 1.345 | K19: 60 | L19: 0 | M19: 0.61 | N19: Chico (35990024)
A21: 1-hexanol
A22: // DATOS DE DENSIDAD Y VISCOSIDAD IMPORTADOS
B23: Lovis / DMA
A24: temperature_c | B24: Unique Sample Id | C24: Date | D24: Time | E24: Sample Name | F24: Master Condition | G24: Density | H24: Density Temperature | I24: Lovis Dyn. Viscosity | J24: Lovis Kin. Viscosity | K24: Lovis Temperature | L24: Lovis Variation Coefficient | M24: Lovis Fw/Bw Deviation | N24: Lovis Current Capillary
A25: 20 | B25: 12811 | C25: 19-11-2025 | D25: 0.33299769 | E25: 1-hexanol_pure | F25: valid | G25: 0.81883 | H25: 19.98 | I25: 5.278 | J25: 6.446 | K25: 20 | L25: 0.04 | M25: 0.35 | N25: Chico (35990024)
A26: 30 | B26: 12812 | C26: 19-11-2025 | D26: 0.33917824 | E26: 1-hexanol_pure | F26: valid | G26: 0.81174 | H26: 29.97 | I26: 3.881 | J26: 4.781 | K26: 30 | L26: 0 | M26: 0.84 | N26: Chico (35990024)
A27: 40 | B27: 12813 | C27: 19-11-2025 | D27: 0.34605324 | E27: 1-hexanol_pure | F27: valid | G27: 0.80455 | H27: 39.97 | I27: 2.919 | J27: 3.628 | K27: 40 | L27: 0.03 | M27: 0.86 | N27: Chico (35990024)
A28: 50 | B28: 12814 | C28: 19-11-2025 | D28: 0.35605324 | E28: 1-hexanol_pure | F28: valid | G28: 0.79722 | H28: 49.98 | I28: 2.24 | J28: 2.809 | K28: 50 | L28: 0.04 | M28: 0.65 | N28: Chico (35990024)
A29: 60 | B29: 12815 | C29: 19-11-2025 | D29: 0.36689815 | E29: 1-hexanol_pure | F29: valid | G29: 0.78971 | H29: 59.98 | I29: 1.75 | J29: 2.216 | K29: 60 | L29: 0.04 | M29: 0.76 | N29: Chico (35990024)
A31: 1-octanol
A32: // DATOS DE DENSIDAD Y VISCOSIDAD IMPORTADOS
B33: Lovis / DMA
A34: temperature_c | B34: Unique Sample Id | C34: Date | D34: Time | E34: Sample Name | F34: Master Condition | G34: Density | H34: Density Temperature | I34: Lovis Dyn. Viscosity | J34: Lovis Kin. Viscosity | K34: Lovis Temperature | L34: Lovis Variation Coefficient | M34: Lovis Fw/Bw Deviation | N34: Lovis Current Capillary
A35: 20 | B35: 12467 | C35: 45909 | D35: 0.51502315 | E35: 1 octanol | F35: valid | G35: 0.82518 | H35: 20.01 | I35: 8.801 | J35: 10.67 | K35: 20 | L35: 0.21 | M35: 0.36 | N35: Chico (35990024)
A36: 30 | B36: 12468 | C36: 45909 | D36: 0.5244213 | E36: 1 octanol | F36: valid | G36: 0.81835 | H36: 29.98 | I36: 6.146 | J36: 7.51 | K36: 30 | L36: 0.34 | M36: 0.39 | N36: Chico (35990024)
A37: 40 | B37: 12469 | C37: 45909 | D37: 0.53439815 | E37: 1 octanol | F37: valid | G37: 0.81141 | H37: 39.98 | I37: 4.454 | J37: 5.49 | K37: 40 | L37: 0.21 | M37: 0.46 | N37: Chico (35990024)
A38: 50 | B38: 12472 | C38: 45909 | D38: 0.5875 | E38: 1 octanol 50 C | F38: valid | G38: 0.80433 | H38: 50.02 | I38: 3.292 | J38: 4.093 | K38: 50 | L38: 0.05 | M38: 1.5 | N38: Chico (35990024)
A39: 60 | B39: 12471 | C39: 45909 | D39: 0.55631944 | E39: 1 octanol | F39: valid | G39: 0.79719 | H39: 59.98 | I39: 2.511 | J39: 3.149 | K39: 60 | L39: 0.05 | M39: 0.19 | N39: Chico (35990024)
A41: MIBK
A42: // DATOS DE DENSIDAD Y VISCOSIDAD IMPORTADOS
B43: Lovis / DMA
...

Sheet dens_visc_beta+2m3b2oh
C1: MM / g/mol | E1: FECHA
A2: beta | B2: 1 | C2: 192.3 | E2: 19/11/2025
A3: 2m3b2oh | B3: 2 | C3: 86.13
E6: Actual
A7: Total Mass (g) | B7: Mass betaionone (trans) / g | C7: Mass 2-methyl-3-buten-2-ol /g | D7: Mole fraction betaionone (trans) | E7: Mass betaionone (tra... (g) | F7: Mass 2-methyl-3-bute... (g) | G7: Mole Fraction betaionone (tra...
A8: 5 | B8: =IF(D8=0, 0, IF(D8=1, A8, (D8*A8*$C$2)/($C$3*(1-D8)+$C$2*D8))) -> 0 | C8: =A8-B8 -> 5 | D8: 0 | E8: 0 | F8: 1 | G8: =IF(AND(E8=0,F8>0),0,"") -> 0
A9: 5 | B9: =IF(D9=0, 0, IF(D9=1, A9, (D9*A9*$C$2)/($C$3*(1-D9)+$C$2*D9))) -> 0.99382927 | C9: =A9-B9 -> 4.0061707 | D9: 0.1 | E9: 1.0138 | F9: 4.0303 | G9: =IFERROR((E9*purity_beta/MW_beta)/((E9*purity_beta/MW_beta)+(F9*purity_2m3b2oh/MW_2m3b2oh)),"") -> 0.099609445
A10: 5 | B10: =IF(D10=0, 0, IF(D10=1, A10, (D10*A10*$C$2)/($C$3*(1-D10)+$C$2*D10))) -> 1.7911032 | C10: =A10-B10 -> 3.2088968 | D10: 0.2 | E10: 1.7936 | F10: 3.2096 | G10: =IFERROR((E10*purity_beta/MW_beta)/((E10*purity_beta/MW_beta)+(F10*purity_2m3b2oh/MW_2m3b2oh)),"") -> 0.19728379
A11: 5 | B11: =IF(D11=0, 0, IF(D11=1, A11, (D11*A11*$C$2)/($C$3*(1-D11)+$C$2*D11))) -> 2.4448852 | C11: =A11-B11 -> 2.5551148 | D11: 0.3 | E11: 2.4454 | F11: 2.5574 | G11: =IFERROR((E11*purity_beta/MW_beta)/((E11*purity_beta/MW_beta)+(F11*purity_2m3b2oh/MW_2m3b2oh)),"") -> 0.29604169
A12: 5 | B12: =IF(D12=0, 0, IF(D12=1, A12, (D12*A12*$C$2)/($C$3*(1-D12)+$C$2*D12))) -> 2.9907153 | C12: =A12-B12 -> 2.0092847 | D12: 0.4 | E12: 3.0027 | F12: 2.0107 | G12: =IFERROR((E12*purity_beta/MW_beta)/((E12*purity_beta/MW_beta)+(F12*purity_2m3b2oh/MW_2m3b2oh)),"") -> 0.39641924
A13: 5 | B13: =IF(D13=0, 0, IF(D13=1, A13, (D13*A13*$C$2)/($C$3*(1-D13)+$C$2*D13))) -> 3.4532917 | C13: =A13-B13 -> 1.5467083 | D13: 0.5 | E13: 3.46 | F13: 1.5684 | G13: =IFERROR((E13*purity_beta/MW_beta)/((E13*purity_beta/MW_beta)+(F13*purity_2m3b2oh/MW_2m3b2oh)),"") -> 0.49244461
A14: 5 | B14: =IF(D14=0, 0, IF(D14=1, A14, (D14*A14*$C$2)/($C$3*(1-D14)+$C$2*D14))) -> 3.8503123 | C14: =A14-B14 -> 1.1496877 | D14: 0.6 | E14: 3.8569 | F14: 1.1532 | G14: =IFERROR((E14*purity_beta/MW_beta)/((E14*purity_beta/MW_beta)+(F14*purity_2m3b2oh/MW_2m3b2oh)),"") -> 0.59529209
A15: 5 | B15: =IF(D15=0, 0, IF(D15=1, A15, (D15*A15*$C$2)/($C$3*(1-D15)+$C$2*D15))) -> 4.1947909 | C15: =A15-B15 -> 0.80520913 | D15: 0.7 | E15: 4.1996 | F15: 0.8142 | G15: =IFERROR((E15*purity_beta/MW_beta)/((E15*purity_beta/MW_beta)+(F15*purity_2m3b2oh/MW_2m3b2oh)),"") -> 0.6940457
A16: 5 | B16: =IF(D16=0, 0, IF(D16=1, A16, (D16*A16*$C$2)/($C$3*(1-D16)+$C$2*D16))) -> 4.4965101 | C16: =A16-B16 -> 0.50348988 | D16: 0.8 | E16: 4.5017 | F16: 0.5032 | G16: =IFERROR((E16*purity_beta/MW_beta)/((E16*purity_beta/MW_beta)+(F16*purity_2m3b2oh/MW_2m3b2oh)),"") -> 0.79734561
A17: 5 | B17: =IF(D17=0, 0, IF(D17=1, A17, (D17*A17*$C$2)/($C$3*(1-D17)+$C$2*D17))) -> 4.7629663 | C17: =A17-B17 -> 0.23703373 | D17: 0.9 | E17: 4.7623 | F17: 0.24 | G17: =IFERROR((E17*purity_beta/MW_beta)/((E17*purity_beta/MW_beta)+(F17*purity_2m3b2oh/MW_2m3b2oh)),"") -> 0.89719236
A18: 5 | B18: =IF(D18=0, 0, IF(D18=1, A18, (D18*A18*$C$2)/($C$3*(1-D18)+$C$2*D18))) -> 5 | C18: =A18-B18 -> 0 | D18: 1 | E18: 5 | F18: 0 | G18: =IF(AND(E18>0,F18=0),1,IFERROR((E18/MW_beta)/((E18/MW_beta)+(F18/MW_2m3b2oh)),"")) -> 1
B21: Densidad | G21: Volumen de Exceso
A22: x1 | B22: 20 | C22: 30 | D22: 40 | E22: 50 | F22: 60 | G22: 20 | H22: 30 | I22: 40 | J22: 50 | K22: 60
A23: =G8 -> 0 | B23: =densidad_viscosidad_puros!G5 -> 0.82388 | C23: =densidad_viscosidad_puros!G6 -> 0.81447 | D23: =densidad_viscosidad_puros!G7 -> 0.8047 | E23: =densidad_viscosidad_puros!G8 -> 0.79458 | F23: =densidad_viscosidad_puros!G9 -> 0.7841 | G23: =IFERROR((($A23*MW_beta)+((1-$A23)*MW_2m3b2oh))/B23-(($A23*MW_beta/B$33)+((1-$A23)*MW_2m3b2oh/B$23)),"") -> 0 | H23: =IFERROR((($A23*MW_beta)+((1-$A23)*MW_2m3b2oh))/C23-(($A23*MW_beta/C$33)+((1-$A23)*MW_2m3b2oh/C$23)),"") -> 0 | I23: =IFERROR((($A23*MW_beta)+((1-$A23)*MW_2m3b2oh))/D23-(($A23*MW_beta/D$33)+((1-$A23)*MW_2m3b2oh/D$23)),"") -> 0 | J23: =IFERROR((($A23*MW_beta)+((1-$A23)*MW_2m3b2oh))/E23-(($A23*MW_beta/E$33)+((1-$A23)*MW_2m3b2oh/E$23)),"") -> 0 | K23: =IFERROR((($A23*MW_beta)+((1-$A23)*MW_2m3b2oh))/F23-(($A23*MW_beta/F$33)+((1-$A23)*MW_2m3b2oh/F$23)),"") -> 0
A24: =G9 -> 0.099609445 | B24: 0.84735 | C24: 0.83789 | D24: 0.8284 | E24: 0.81866 | F24: 0.80867 | G24: =IFERROR((($A24*MW_beta)+((1-$A24)*MW_2m3b2oh))/B24-(($A24*MW_beta/B$33)+((1-$A24)*MW_2m3b2oh/B$23)),"") -> -0.27169592 | H24: =IFERROR((($A24*MW_beta)+((1-$A24)*MW_2m3b2oh))/C24-(($A24*MW_beta/C$33)+((1-$A24)*MW_2m3b2oh/C$23)),"") -> -0.23764907 | I24: =IFERROR((($A24*MW_beta)+((1-$A24)*MW_2m3b2oh))/D24-(($A24*MW_beta/D$33)+((1-$A24)*MW_2m3b2oh/D$23)),"") -> -0.24212496 | J24: =IFERROR((($A24*MW_beta)+((1-$A24)*MW_2m3b2oh))/E24-(($A24*MW_beta/E$33)+((1-$A24)*MW_2m3b2oh/E$23)),"") -> -0.2546065 | K24: =IFERROR((($A24*MW_beta)+((1-$A24)*MW_2m3b2oh))/F24-(($A24*MW_beta/F$33)+((1-$A24)*MW_2m3b2oh/F$23)),"") -> -0.27624335
A25: =G10 -> 0.19728379 | B25: 0.86523 | C25: 0.85629 | D25: 0.84711 | E25: 0.83774 | F25: 0.82815 | G25: =IFERROR((($A25*MW_beta)+((1-$A25)*MW_2m3b2oh))/B25-(($A25*MW_beta/B$33)+((1-$A25)*MW_2m3b2oh/B$23)),"") -> -0.31009368 | H25: =IFERROR((($A25*MW_beta)+((1-$A25)*MW_2m3b2oh))/C25-(($A25*MW_beta/C$33)+((1-$A25)*MW_2m3b2oh/C$23)),"") -> -0.31827546 | I25: =IFERROR((($A25*MW_beta)+((1-$A25)*MW_2m3b2oh))/D25-(($A25*MW_beta/D$33)+((1-$A25)*MW_2m3b2oh/D$23)),"") -> -0.33172661 | J25: =IFERROR((($A25*MW_beta)+((1-$A25)*MW_2m3b2oh))/E25-(($A25*MW_beta/E$33)+((1-$A25)*MW_2m3b2oh/E$23)),"") -> -0.35673114 | K25: =IFERROR((($A25*MW_beta)+((1-$A25)*MW_2m3b2oh))/F25-(($A25*MW_beta/F$33)+((1-$A25)*MW_2m3b2oh/F$23)),"") -> -0.38906901
A26: =G11 -> 0.29604169 | B26: 0.88031 | C26: 0.87163 | D26: 0.86274 | E26: 0.8537 | F26: 0.84448 | G26: =IFERROR((($A26*MW_beta)+((1-$A26)*MW_2m3b2oh))/B26-(($A26*MW_beta/B$33)+((1-$A26)*MW_2m3b2oh/B$23)),"") -> -0.29185239 | H26: =IFERROR((($A26*MW_beta)+((1-$A26)*MW_2m3b2oh))/C26-(($A26*MW_beta/C$33)+((1-$A26)*MW_2m3b2oh/C$23)),"") -> -0.30843872 | I26: =IFERROR((($A26*MW_beta)+((1-$A26)*MW_2m3b2oh))/D26-(($A26*MW_beta/D$33)+((1-$A26)*MW_2m3b2oh/D$23)),"") -> -0.3295592 | J26: =IFERROR((($A26*MW_beta)+((1-$A26)*MW_2m3b2oh))/E26-(($A26*MW_beta/E$33)+((1-$A26)*MW_2m3b2oh/E$23)),"") -> -0.36324014 | K26: =IFERROR((($A26*MW_beta)+((1-$A26)*MW_2m3b2oh))/F26-(($A26*MW_beta/F$33)+((1-$A26)*MW_2m3b2oh/F$23)),"") -> -0.40405348
A27: =G12 -> 0.39641924 | B27: 0.89316 | C27: 0.8848 | D27: 0.87617 | E27: 0.86742 | F27: 0.85853 | G27: =IFERROR((($A27*MW_beta)+((1-$A27)*MW_2m3b2oh))/B27-(($A27*MW_beta/B$33)+((1-$A27)*MW_2m3b2oh/B$23)),"") -> -0.2140936 | H27: =IFERROR((($A27*MW_beta)+((1-$A27)*MW_2m3b2oh))/C27-(($A27*MW_beta/C$33)+((1-$A27)*MW_2m3b2oh/C$23)),"") -> -0.25119815 | I27: =IFERROR((($A27*MW_beta)+((1-$A27)*MW_2m3b2oh))/D27-(($A27*MW_beta/D$33)+((1-$A27)*MW_2m3b2oh/D$23)),"") -> -0.27784243 | J27: =IFERROR((($A27*MW_beta)+((1-$A27)*MW_2m3b2oh))/E27-(($A27*MW_beta/E$33)+((1-$A27)*MW_2m3b2oh/E$23)),"") -> -0.31672659 | K27: =IFERROR((($A27*MW_beta)+((1-$A27)*MW_2m3b2oh))/F27-(($A27*MW_beta/F$33)+((1-$A27)*MW_2m3b2oh/F$23)),"") -> -0.36279228
A28: =G13 -> 0.49244461 | B28: 0.90411 | C28: 0.89579 | D28: 0.88735 | E28: 0.87883 | F28: 0.8702 | G28: =IFERROR((($A28*MW_beta)+((1-$A28)*MW_2m3b2oh))/B28-(($A28*MW_beta/B$33)+((1-$A28)*MW_2m3b2oh/B$23)),"") -> -0.17858269 | H28: =IFERROR((($A28*MW_beta)+((1-$A28)*MW_2m3b2oh))/C28-(($A28*MW_beta/C$33)+((1-$A28)*MW_2m3b2oh/C$23)),"") -> -0.19512472 | I28: =IFERROR((($A28*MW_beta)+((1-$A28)*MW_2m3b2oh))/D28-(($A28*MW_beta/D$33)+((1-$A28)*MW_2m3b2oh/D$23)),"") -> -0.22063289 | J28: =IFERROR((($A28*MW_beta)+((1-$A28)*MW_2m3b2oh))/E28-(($A28*MW_beta/E$33)+((1-$A28)*MW_2m3b2oh/E$23)),"") -> -0.26025369 | K28: =IFERROR((($A28*MW_beta)+((1-$A28)*MW_2m3b2oh))/F28-(($A28*MW_beta/F$33)+((1-$A28)*MW_2m3b2oh/F$23)),"") -> -0.3059736
A29: =G14 -> 0.59529209 | B29: 0.91437 | C29: 0.90623 | D29: 0.89798 | E29: 0.88967 | F29: 0.88128 | G29: =IFERROR((($A29*MW_beta)+((1-$A29)*MW_2m3b2oh))/B29-(($A29*MW_beta/B$33)+((1-$A29)*MW_2m3b2oh/B$23)),"") -> -0.13172741 | H29: =IFERROR((($A29*MW_beta)+((1-$A29)*MW_2m3b2oh))/C29-(($A29*MW_beta/C$33)+((1-$A29)*MW_2m3b2oh/C$23)),"") -> -0.15138912 | I29: =IFERROR((($A29*MW_beta)+((1-$A29)*MW_2m3b2oh))/D29-(($A29*MW_beta/D$33)+((1-$A29)*MW_2m3b2oh/D$23)),"") -> -0.17676126 | J29: =IFERROR((($A29*MW_beta)+((1-$A29)*MW_2m3b2oh))/E29-(($A29*MW_beta/E$33)+((1-$A29)*MW_2m3b2oh/E$23)),"") -> -0.21469013 | K29: =IFERROR((($A29*MW_beta)+((1-$A29)*MW_2m3b2oh))/F29-(($A29*MW_beta/F$33)+((1-$A29)*MW_2m3b2oh/F$23)),"") -> -0.25754039
A30: =G15 -> 0.6940457 | B30: 0.92296 | C30: 0.91494 | D30: 0.90684 | E30: 0.89866 | F30: 0.89054 | G30: =IFERROR((($A30*MW_beta)+((1-$A30)*MW_2m3b2oh))/B30-(($A30*MW_beta/B$33)+((1-$A30)*MW_2m3b2oh/B$23)),"") -> -0.063997305 | H30: =IFERROR((($A30*MW_beta)+((1-$A30)*MW_2m3b2oh))/C30-(($A30*MW_beta/C$33)+((1-$A30)*MW_2m3b2oh/C$23)),"") -> -0.079040884 | I30: =IFERROR((($A30*MW_beta)+((1-$A30)*MW_2m3b2oh))/D30-(($A30*MW_beta/D$33)+((1-$A30)*MW_2m3b2oh/D$23)),"") -> -0.10047876 | J30: =IFERROR((($A30*MW_beta)+((1-$A30)*MW_2m3b2oh))/E30-(($A30*MW_beta/E$33)+((1-$A30)*MW_2m3b2oh/E$23)),"") -> -0.12538029 | K30: =IFERROR((($A30*MW_beta)+((1-$A30)*MW_2m3b2oh))/F30-(($A30*MW_beta/F$33)+((1-$A30)*MW_2m3b2oh/F$23)),"") -> -0.1765248
A31: =G16 -> 0.79734561 | B31: 0.93115 | C31: 0.92328 | D31: 0.91532 | E31: 0.90733 | F31: 0.8993 | G31: =IFERROR((($A31*MW_beta)+((1-$A31)*MW_2m3b2oh))/B31-(($A31*MW_beta/B$33)+((1-$A31)*MW_2m3b2oh/B$23)),"") -> -0.030710249 | H31: =IFERROR((($A31*MW_beta)+((1-$A31)*MW_2m3b2oh))/C31-(($A31*MW_beta/C$33)+((1-$A31)*MW_2m3b2oh/C$23)),"") -> -0.048558676 | I31: =IFERROR((($A31*MW_beta)+((1-$A31)*MW_2m3b2oh))/D31-(($A31*MW_beta/D$33)+((1-$A31)*MW_2m3b2oh/D$23)),"") -> -0.065900426 | J31: =IFERROR((($A31*MW_beta)+((1-$A31)*MW_2m3b2oh))/E31-(($A31*MW_beta/E$33)+((1-$A31)*MW_2m3b2oh/E$23)),"") -> -0.091468531 | K31: =IFERROR((($A31*MW_beta)+((1-$A31)*MW_2m3b2oh))/F31-(($A31*MW_beta/F$33)+((1-$A31)*MW_2m3b2oh/F$23)),"") -> -0.11677294
A32: =G17 -> 0.89719236 | B32: 0.93847 | C32: 0.93065 | D32: 0.92277 | E32: 0.91489 | F32: 0.90704 | G32: =IFERROR((($A32*MW_beta)+((1-$A32)*MW_2m3b2oh))/B32-(($A32*MW_beta/B$33)+((1-$A32)*MW_2m3b2oh/B$23)),"") -> -0.045834283 | H32: =IFERROR((($A32*MW_beta)+((1-$A32)*MW_2m3b2oh))/C32-(($A32*MW_beta/C$33)+((1-$A32)*MW_2m3b2oh/C$23)),"") -> -0.04978414 | I32: =IFERROR((($A32*MW_beta)+((1-$A32)*MW_2m3b2oh))/D32-(($A32*MW_beta/D$33)+((1-$A32)*MW_2m3b2oh/D$23)),"") -> -0.054219614 | J32: =IFERROR((($A32*MW_beta)+((1-$A32)*MW_2m3b2oh))/E32-(($A32*MW_beta/E$33)+((1-$A32)*MW_2m3b2oh/E$23)),"") -> -0.068073522 | K32: =IFERROR((($A32*MW_beta)+((1-$A32)*MW_2m3b2oh))/F32-(($A32*MW_beta/F$33)+((1-$A32)*MW_2m3b2oh/F$23)),"") -> -0.090465546
A33: =G18 -> 1 | B33: =densidad_viscosidad_puros!G65 -> 0.94498 | C33: =densidad_viscosidad_puros!G66 -> 0.93726 | D33: =densidad_viscosidad_puros!G67 -> 0.9295 | E33: =densidad_viscosidad_puros!G68 -> 0.92172 | F33: =densidad_viscosidad_puros!G69 -> 0.91396 | G33: =IFERROR((($A33*MW_beta)+((1-$A33)*MW_2m3b2oh))/B33-(($A33*MW_beta/B$33)+((1-$A33)*MW_2m3b2oh/B$23)),"") -> 0 | H33: =IFERROR((($A33*MW_beta)+((1-$A33)*MW_2m3b2oh))/C33-(($A33*MW_beta/C$33)+((1-$A33)*MW_2m3b2oh/C$23)),"") -> 0 | I33: =IFERROR((($A33*MW_beta)+((1-$A33)*MW_2m3b2oh))/D33-(($A33*MW_beta/D$33)+((1-$A33)*MW_2m3b2oh/D$23)),"") -> 0 | J33: =IFERROR((($A33*MW_beta)+((1-$A33)*MW_2m3b2oh))/E33-(($A33*MW_beta/E$33)+((1-$A33)*MW_2m3b2oh/E$23)),"") -> 0 | K33: =IFERROR((($A33*MW_beta)+((1-$A33)*MW_2m3b2oh))/F33-(($A33*MW_beta/F$33)+((1-$A33)*MW_2m3b2oh/F$23)),"") -> 0
B35: Viscosidad
A36: x1 | B36: 20 | C36: 30 | D36: 40 | E36: 50 | F36: 60
A37: =G8 -> 0 | B37: =densidad_viscosidad_puros!I5 -> 2.353 | C37: =densidad_viscosidad_puros!I6 -> 1.682 | D37: =densidad_viscosidad_puros!I7 -> 1.247 | E37: =densidad_viscosidad_puros!I8 -> 0.964 | F37: =densidad_viscosidad_puros!I9 -> 0.757
A38: =G9 -> 0.099609445 | B38: =H53 -> 2.826 | C38: =H54 -> 2.021 | D38: =H55 -> 1.502 | E38: =H56 -> 1.154 | F38: =H57 -> 0.912
A39: =G10 -> 0.19728379 | B39: 3.278 | C39: 2.35 | D39: 1.753 | E39: 1.352 | F39: 1.073
A40: =G11 -> 0.29604169 | B40: 3.764 | C40: 2.698 | D40: 2.016 | E40: 1.56 | F40: 1.241
A41: =G12 -> 0.39641924 | B41: 4.321 | C41: 3.087 | D41: 2.304 | E41: 1.783 | F41: 1.42
A42: =G13 -> 0.49244461 | B42: 4.948 | C42: 3.51 | D42: 2.61 | E42: 2.016 | F42: 1.605
A43: =G14 -> 0.59529209 | B43: 5.757 | C43: 4.038 | D43: 2.986 | E43: 2.296 | F43: 1.824
A44: =G15 -> 0.6940457 | B44: 6.687 | C44: 4.636 | D44: 3.396 | E44: 2.59 | F44: 2.051
A45: =G16 -> 0.79734561 | B45: 7.915 | C45: 5.372 | D45: 3.883 | E45: 2.945 | F45: 2.317
...

Sheet dens_visc_beta+2m2boh
C1: MM / g/mol
A2: beta | B2: 1 | C2: 192.3
A3: 2m2boh | B3: 2 | C3: 88.15
E6: Actual
A7: Total Mass (g) | B7: Mass betaionone (trans) / g | C7: Mass 2-methyl-2-butanol /g | D7: Mole fraction betaionone (trans) | E7: Mass betaionone (tra... (g) | F7: Mass 2-methyl-2-buta... (g) | G7: Mole Fraction betaionone (tra...
A8: 5 | B8: =IF(D8=0, 0, IF(D8=1, A8, (D8*A8*$C$2)/($C$3*(1-D8)+$C$2*D8))) -> 0 | C8: =A8-B8 -> 5 | D8: 0 | E8: 0 | F8: 1 | G8: =IF(AND(E8=0,F8>0),0,"") -> 0
A9: 5 | B9: =IF(D9=0, 0, IF(D9=1, A9, (D9*A9*$C$2)/($C$3*(1-D9)+$C$2*D9))) -> 0.9754984 | C9: =A9-B9 -> 4.0245016 | D9: 0.1 | G9: =IFERROR((E9*purity_beta/MW_beta)/((E9*purity_beta/MW_beta)+(F9*purity_2m2boh/MW_2m2boh)),"")
A10: 5 | B10: =IF(D10=0, 0, IF(D10=1, A10, (D10*A10*$C$2)/($C$3*(1-D10)+$C$2*D10))) -> 1.764544 | C10: =A10-B10 -> 3.235456 | D10: 0.2 | G10: =IFERROR((E10*purity_beta/MW_beta)/((E10*purity_beta/MW_beta)+(F10*purity_2m2boh/MW_2m2boh)),"")
A11: 5 | B11: =IF(D11=0, 0, IF(D11=1, A11, (D11*A11*$C$2)/($C$3*(1-D11)+$C$2*D11))) -> 2.4159303 | C11: =A11-B11 -> 2.5840697 | D11: 0.3 | G11: =IFERROR((E11*purity_beta/MW_beta)/((E11*purity_beta/MW_beta)+(F11*purity_2m2boh/MW_2m2boh)),"")
A12: 5 | B12: =IF(D12=0, 0, IF(D12=1, A12, (D12*A12*$C$2)/($C$3*(1-D12)+$C$2*D12))) -> 2.9627918 | C12: =A12-B12 -> 2.0372082 | D12: 0.4 | G12: =IFERROR((E12*purity_beta/MW_beta)/((E12*purity_beta/MW_beta)+(F12*purity_2m2boh/MW_2m2boh)),"")
A13: 5 | B13: =IF(D13=0, 0, IF(D13=1, A13, (D13*A13*$C$2)/($C$3*(1-D13)+$C$2*D13))) -> 3.4284186 | C13: =A13-B13 -> 1.5715814 | D13: 0.5 | G13: =IFERROR((E13*purity_beta/MW_beta)/((E13*purity_beta/MW_beta)+(F13*purity_2m2boh/MW_2m2boh)),"")
A14: 5 | B14: =IF(D14=0, 0, IF(D14=1, A14, (D14*A14*$C$2)/($C$3*(1-D14)+$C$2*D14))) -> 3.8296601 | C14: =A14-B14 -> 1.1703399 | D14: 0.6 | G14: =IFERROR((E14*purity_beta/MW_beta)/((E14*purity_beta/MW_beta)+(F14*purity_2m2boh/MW_2m2boh)),"")
A15: 5 | B15: =IF(D15=0, 0, IF(D15=1, A15, (D15*A15*$C$2)/($C$3*(1-D15)+$C$2*D15))) -> 4.1790072 | C15: =A15-B15 -> 0.82099283 | D15: 0.7 | G15: =IFERROR((E15*purity_beta/MW_beta)/((E15*purity_beta/MW_beta)+(F15*purity_2m2boh/MW_2m2boh)),"")
A16: 5 | B16: =IF(D16=0, 0, IF(D16=1, A16, (D16*A16*$C$2)/($C$3*(1-D16)+$C$2*D16))) -> 4.4859159 | C16: =A16-B16 -> 0.5140841 | D16: 0.8 | G16: =IFERROR((E16*purity_beta/MW_beta)/((E16*purity_beta/MW_beta)+(F16*purity_2m2boh/MW_2m2boh)),"")
A17: 5 | B17: =IF(D17=0, 0, IF(D17=1, A17, (D17*A17*$C$2)/($C$3*(1-D17)+$C$2*D17))) -> 4.7576766 | C17: =A17-B17 -> 0.24232345 | D17: 0.9 | G17: =IFERROR((E17*purity_beta/MW_beta)/((E17*purity_beta/MW_beta)+(F17*purity_2m2boh/MW_2m2boh)),"")
A18: 5 | B18: =IF(D18=0, 0, IF(D18=1, A18, (D18*A18*$C$2)/($C$3*(1-D18)+$C$2*D18))) -> 5 | C18: =A18-B18 -> 0 | D18: 1 | E18: 1 | F18: 0 | G18: =IF(AND(E18>0,F18=0),1,IFERROR((E18/MW_beta)/((E18/MW_beta)+(F18/MW_2m2boh)),"")) -> 1
A20: Volumen de exceso
B21: Densidad | G21: Volumen de Exceso
A22: x1 | B22: 20 | C22: 30 | D22: 40 | E22: 50 | F22: 60 | G22: 20 | H22: 30 | I22: 40 | J22: 50 | K22: 60
A23: =G8 -> 0 | B23: =densidad_viscosidad_puros!G15 -> 0.80899 | C23: =densidad_viscosidad_puros!G16 -> 0.79979 | D23: =densidad_viscosidad_puros!G17 -> 0.79035 | E23: =densidad_viscosidad_puros!G18 -> 0.7806 | F23: =densidad_viscosidad_puros!G19 -> 0.77049 | G23: =IFERROR((($A23*MW_beta)+((1-$A23)*MW_2m2boh))/B23-(($A23*MW_beta/B$33)+((1-$A23)*MW_2m2boh/B$23)),"") -> 0 | H23: =IFERROR((($A23*MW_beta)+((1-$A23)*MW_2m2boh))/C23-(($A23*MW_beta/C$33)+((1-$A23)*MW_2m2boh/C$23)),"") -> 0 | I23: =IFERROR((($A23*MW_beta)+((1-$A23)*MW_2m2boh))/D23-(($A23*MW_beta/D$33)+((1-$A23)*MW_2m2boh/D$23)),"") -> 0 | J23: =IFERROR((($A23*MW_beta)+((1-$A23)*MW_2m2boh))/E23-(($A23*MW_beta/E$33)+((1-$A23)*MW_2m2boh/E$23)),"") -> 0 | K23: =IFERROR((($A23*MW_beta)+((1-$A23)*MW_2m2boh))/F23-(($A23*MW_beta/F$33)+((1-$A23)*MW_2m2boh/F$23)),"") -> 0
A24: =G9 | G24: =IFERROR((($A24*MW_beta)+((1-$A24)*MW_2m2boh))/B24-(($A24*MW_beta/B$33)+((1-$A24)*MW_2m2boh/B$23)),"") | H24: =IFERROR((($A24*MW_beta)+((1-$A24)*MW_2m2boh))/C24-(($A24*MW_beta/C$33)+((1-$A24)*MW_2m2boh/C$23)),"") | I24: =IFERROR((($A24*MW_beta)+((1-$A24)*MW_2m2boh))/D24-(($A24*MW_beta/D$33)+((1-$A24)*MW_2m2boh/D$23)),"") | J24: =IFERROR((($A24*MW_beta)+((1-$A24)*MW_2m2boh))/E24-(($A24*MW_beta/E$33)+((1-$A24)*MW_2m2boh/E$23)),"") | K24: =IFERROR((($A24*MW_beta)+((1-$A24)*MW_2m2boh))/F24-(($A24*MW_beta/F$33)+((1-$A24)*MW_2m2boh/F$23)),"")
A25: =G10 | G25: =IFERROR((($A25*MW_beta)+((1-$A25)*MW_2m2boh))/B25-(($A25*MW_beta/B$33)+((1-$A25)*MW_2m2boh/B$23)),"") | H25: =IFERROR((($A25*MW_beta)+((1-$A25)*MW_2m2boh))/C25-(($A25*MW_beta/C$33)+((1-$A25)*MW_2m2boh/C$23)),"") | I25: =IFERROR((($A25*MW_beta)+((1-$A25)*MW_2m2boh))/D25-(($A25*MW_beta/D$33)+((1-$A25)*MW_2m2boh/D$23)),"") | J25: =IFERROR((($A25*MW_beta)+((1-$A25)*MW_2m2boh))/E25-(($A25*MW_beta/E$33)+((1-$A25)*MW_2m2boh/E$23)),"") | K25: =IFERROR((($A25*MW_beta)+((1-$A25)*MW_2m2boh))/F25-(($A25*MW_beta/F$33)+((1-$A25)*MW_2m2boh/F$23)),"")
A26: =G11 | G26: =IFERROR((($A26*MW_beta)+((1-$A26)*MW_2m2boh))/B26-(($A26*MW_beta/B$33)+((1-$A26)*MW_2m2boh/B$23)),"") | H26: =IFERROR((($A26*MW_beta)+((1-$A26)*MW_2m2boh))/C26-(($A26*MW_beta/C$33)+((1-$A26)*MW_2m2boh/C$23)),"") | I26: =IFERROR((($A26*MW_beta)+((1-$A26)*MW_2m2boh))/D26-(($A26*MW_beta/D$33)+((1-$A26)*MW_2m2boh/D$23)),"") | J26: =IFERROR((($A26*MW_beta)+((1-$A26)*MW_2m2boh))/E26-(($A26*MW_beta/E$33)+((1-$A26)*MW_2m2boh/E$23)),"") | K26: =IFERROR((($A26*MW_beta)+((1-$A26)*MW_2m2boh))/F26-(($A26*MW_beta/F$33)+((1-$A26)*MW_2m2boh/F$23)),"")
A27: =G12 | G27: =IFERROR((($A27*MW_beta)+((1-$A27)*MW_2m2boh))/B27-(($A27*MW_beta/B$33)+((1-$A27)*MW_2m2boh/B$23)),"") | H27: =IFERROR((($A27*MW_beta)+((1-$A27)*MW_2m2boh))/C27-(($A27*MW_beta/C$33)+((1-$A27)*MW_2m2boh/C$23)),"") | I27: =IFERROR((($A27*MW_beta)+((1-$A27)*MW_2m2boh))/D27-(($A27*MW_beta/D$33)+((1-$A27)*MW_2m2boh/D$23)),"") | J27: =IFERROR((($A27*MW_beta)+((1-$A27)*MW_2m2boh))/E27-(($A27*MW_beta/E$33)+((1-$A27)*MW_2m2boh/E$23)),"") | K27: =IFERROR((($A27*MW_beta)+((1-$A27)*MW_2m2boh))/F27-(($A27*MW_beta/F$33)+((1-$A27)*MW_2m2boh/F$23)),"")
A28: =G13 | G28: =IFERROR((($A28*MW_beta)+((1-$A28)*MW_2m2boh))/B28-(($A28*MW_beta/B$33)+((1-$A28)*MW_2m2boh/B$23)),"") | H28: =IFERROR((($A28*MW_beta)+((1-$A28)*MW_2m2boh))/C28-(($A28*MW_beta/C$33)+((1-$A28)*MW_2m2boh/C$23)),"") | I28: =IFERROR((($A28*MW_beta)+((1-$A28)*MW_2m2boh))/D28-(($A28*MW_beta/D$33)+((1-$A28)*MW_2m2boh/D$23)),"") | J28: =IFERROR((($A28*MW_beta)+((1-$A28)*MW_2m2boh))/E28-(($A28*MW_beta/E$33)+((1-$A28)*MW_2m2boh/E$23)),"") | K28: =IFERROR((($A28*MW_beta)+((1-$A28)*MW_2m2boh))/F28-(($A28*MW_beta/F$33)+((1-$A28)*MW_2m2boh/F$23)),"")
A29: =G14 | G29: =IFERROR((($A29*MW_beta)+((1-$A29)*MW_2m2boh))/B29-(($A29*MW_beta/B$33)+((1-$A29)*MW_2m2boh/B$23)),"") | H29: =IFERROR((($A29*MW_beta)+((1-$A29)*MW_2m2boh))/C29-(($A29*MW_beta/C$33)+((1-$A29)*MW_2m2boh/C$23)),"") | I29: =IFERROR((($A29*MW_beta)+((1-$A29)*MW_2m2boh))/D29-(($A29*MW_beta/D$33)+((1-$A29)*MW_2m2boh/D$23)),"") | J29: =IFERROR((($A29*MW_beta)+((1-$A29)*MW_2m2boh))/E29-(($A29*MW_beta/E$33)+((1-$A29)*MW_2m2boh/E$23)),"") | K29: =IFERROR((($A29*MW_beta)+((1-$A29)*MW_2m2boh))/F29-(($A29*MW_beta/F$33)+((1-$A29)*MW_2m2boh/F$23)),"")
A30: =G15 | G30: =IFERROR((($A30*MW_beta)+((1-$A30)*MW_2m2boh))/B30-(($A30*MW_beta/B$33)+((1-$A30)*MW_2m2boh/B$23)),"") | H30: =IFERROR((($A30*MW_beta)+((1-$A30)*MW_2m2boh))/C30-(($A30*MW_beta/C$33)+((1-$A30)*MW_2m2boh/C$23)),"") | I30: =IFERROR((($A30*MW_beta)+((1-$A30)*MW_2m2boh))/D30-(($A30*MW_beta/D$33)+((1-$A30)*MW_2m2boh/D$23)),"") | J30: =IFERROR((($A30*MW_beta)+((1-$A30)*MW_2m2boh))/E30-(($A30*MW_beta/E$33)+((1-$A30)*MW_2m2boh/E$23)),"") | K30: =IFERROR((($A30*MW_beta)+((1-$A30)*MW_2m2boh))/F30-(($A30*MW_beta/F$33)+((1-$A30)*MW_2m2boh/F$23)),"")
A31: =G16 | G31: =IFERROR((($A31*MW_beta)+((1-$A31)*MW_2m2boh))/B31-(($A31*MW_beta/B$33)+((1-$A31)*MW_2m2boh/B$23)),"") | H31: =IFERROR((($A31*MW_beta)+((1-$A31)*MW_2m2boh))/C31-(($A31*MW_beta/C$33)+((1-$A31)*MW_2m2boh/C$23)),"") | I31: =IFERROR((($A31*MW_beta)+((1-$A31)*MW_2m2boh))/D31-(($A31*MW_beta/D$33)+((1-$A31)*MW_2m2boh/D$23)),"") | J31: =IFERROR((($A31*MW_beta)+((1-$A31)*MW_2m2boh))/E31-(($A31*MW_beta/E$33)+((1-$A31)*MW_2m2boh/E$23)),"") | K31: =IFERROR((($A31*MW_beta)+((1-$A31)*MW_2m2boh))/F31-(($A31*MW_beta/F$33)+((1-$A31)*MW_2m2boh/F$23)),"")
A32: =G17 | G32: =IFERROR((($A32*MW_beta)+((1-$A32)*MW_2m2boh))/B32-(($A32*MW_beta/B$33)+((1-$A32)*MW_2m2boh/B$23)),"") | H32: =IFERROR((($A32*MW_beta)+((1-$A32)*MW_2m2boh))/C32-(($A32*MW_beta/C$33)+((1-$A32)*MW_2m2boh/C$23)),"") | I32: =IFERROR((($A32*MW_beta)+((1-$A32)*MW_2m2boh))/D32-(($A32*MW_beta/D$33)+((1-$A32)*MW_2m2boh/D$23)),"") | J32: =IFERROR((($A32*MW_beta)+((1-$A32)*MW_2m2boh))/E32-(($A32*MW_beta/E$33)+((1-$A32)*MW_2m2boh/E$23)),"") | K32: =IFERROR((($A32*MW_beta)+((1-$A32)*MW_2m2boh))/F32-(($A32*MW_beta/F$33)+((1-$A32)*MW_2m2boh/F$23)),"")
A33: =G18 -> 1 | B33: =densidad_viscosidad_puros!G65 -> 0.94498 | C33: =densidad_viscosidad_puros!G66 -> 0.93726 | D33: =densidad_viscosidad_puros!G67 -> 0.9295 | E33: =densidad_viscosidad_puros!G68 -> 0.92172 | F33: =densidad_viscosidad_puros!G69 -> 0.91396 | G33: =IFERROR((($A33*MW_beta)+((1-$A33)*MW_2m2boh))/B33-(($A33*MW_beta/B$33)+((1-$A33)*MW_2m2boh/B$23)),"") -> 0 | H33: =IFERROR((($A33*MW_beta)+((1-$A33)*MW_2m2boh))/C33-(($A33*MW_beta/C$33)+((1-$A33)*MW_2m2boh/C$23)),"") -> 0 | I33: =IFERROR((($A33*MW_beta)+((1-$A33)*MW_2m2boh))/D33-(($A33*MW_beta/D$33)+((1-$A33)*MW_2m2boh/D$23)),"") -> 0 | J33: =IFERROR((($A33*MW_beta)+((1-$A33)*MW_2m2boh))/E33-(($A33*MW_beta/E$33)+((1-$A33)*MW_2m2boh/E$23)),"") -> 0 | K33: =IFERROR((($A33*MW_beta)+((1-$A33)*MW_2m2boh))/F33-(($A33*MW_beta/F$33)+((1-$A33)*MW_2m2boh/F$23)),"") -> 0
B35: Viscosidad
A36: x1 | B36: 20 | C36: 30 | D36: 40 | E36: 50 | F36: 60
A37: =G8 -> 0 | B37: =densidad_viscosidad_puros!I15 -> 4.244 | C37: =densidad_viscosidad_puros!I16 -> 2.776 | D37: =densidad_viscosidad_puros!I17 -> 1.918 | E37: =densidad_viscosidad_puros!I18 -> 1.397 | F37: =densidad_viscosidad_puros!I19 -> 1.036
A38: =G9
A39: =G10
A40: =G11
A41: =G12
A42: =G13
A43: =G14
A44: =G15
...

Sheet dens_visc_beta+1hexoh
C1: MM / g/mol
A2: beta | B2: 1 | C2: 192.3
A3: hexoh | B3: 2 | C3: 102.17
E6: Actual
A7: Total Mass (g) | B7: Mass betaionone (trans) / g | C7: Mass 1-hexanol /g | D7: Mole fraction betaionone (trans) | E7: Mass betaionone (tra... (g) | F7: Mass 1-hexanol... (g) | G7: Mole Fraction betaionone (tra...
A8: 5 | B8: =IF(D8=0, 0, IF(D8=1, A8, (D8*A8*$C$2)/($C$3*(1-D8)+$C$2*D8))) -> 0 | C8: =A8-B8 -> 5 | D8: 0 | G8: =IF(AND(E8=0,F8>0),0,"")
A9: 5 | B9: =IF(D9=0, 0, IF(D9=1, A9, (D9*A9*$C$2)/($C$3*(1-D9)+$C$2*D9))) -> 0.86479048 | C9: =A9-B9 -> 4.1352095 | D9: 0.1 | G9: =IFERROR((E9*purity_beta/MW_beta)/((E9*purity_beta/MW_beta)+(F9*purity_hexoh/MW_hexoh)),"")
A10: 5 | B10: =IF(D10=0, 0, IF(D10=1, A10, (D10*A10*$C$2)/($C$3*(1-D10)+$C$2*D10))) -> 1.5998869 | C10: =A10-B10 -> 3.4001131 | D10: 0.2 | G10: =IFERROR((E10*purity_beta/MW_beta)/((E10*purity_beta/MW_beta)+(F10*purity_hexoh/MW_hexoh)),"")
A11: 5 | B11: =IF(D11=0, 0, IF(D11=1, A11, (D11*A11*$C$2)/($C$3*(1-D11)+$C$2*D11))) -> 2.2324296 | C11: =A11-B11 -> 2.7675704 | D11: 0.3 | G11: =IFERROR((E11*purity_beta/MW_beta)/((E11*purity_beta/MW_beta)+(F11*purity_hexoh/MW_hexoh)),"")
A12: 5 | B12: =IF(D12=0, 0, IF(D12=1, A12, (D12*A12*$C$2)/($C$3*(1-D12)+$C$2*D12))) -> 2.7824804 | C12: =A12-B12 -> 2.2175196 | D12: 0.4 | G12: =IFERROR((E12*purity_beta/MW_beta)/((E12*purity_beta/MW_beta)+(F12*purity_hexoh/MW_hexoh)),"")
A13: 5 | B13: =IF(D13=0, 0, IF(D13=1, A13, (D13*A13*$C$2)/($C$3*(1-D13)+$C$2*D13))) -> 3.2651883 | C13: =A13-B13 -> 1.7348117 | D13: 0.5 | G13: =IFERROR((E13*purity_beta/MW_beta)/((E13*purity_beta/MW_beta)+(F13*purity_hexoh/MW_hexoh)),"")
A14: 5 | B14: =IF(D14=0, 0, IF(D14=1, A14, (D14*A14*$C$2)/($C$3*(1-D14)+$C$2*D14))) -> 3.6922073 | C14: =A14-B14 -> 1.3077927 | D14: 0.6 | G14: =IFERROR((E14*purity_beta/MW_beta)/((E14*purity_beta/MW_beta)+(F14*purity_hexoh/MW_hexoh)),"")
A15: 5 | B15: =IF(D15=0, 0, IF(D15=1, A15, (D15*A15*$C$2)/($C$3*(1-D15)+$C$2*D15))) -> 4.0726487 | C15: =A15-B15 -> 0.92735128 | D15: 0.7 | G15: =IFERROR((E15*purity_beta/MW_beta)/((E15*purity_beta/MW_beta)+(F15*purity_hexoh/MW_hexoh)),"")
A16: 5 | B16: =IF(D16=0, 0, IF(D16=1, A16, (D16*A16*$C$2)/($C$3*(1-D16)+$C$2*D16))) -> 4.4137393 | C16: =A16-B16 -> 0.58626072 | D16: 0.8 | G16: =IFERROR((E16*purity_beta/MW_beta)/((E16*purity_beta/MW_beta)+(F16*purity_hexoh/MW_hexoh)),"")
A17: 5 | B17: =IF(D17=0, 0, IF(D17=1, A17, (D17*A17*$C$2)/($C$3*(1-D17)+$C$2*D17))) -> 4.7212841 | C17: =A17-B17 -> 0.27871589 | D17: 0.9 | G17: =IFERROR((E17*purity_beta/MW_beta)/((E17*purity_beta/MW_beta)+(F17*purity_hexoh/MW_hexoh)),"")
A18: 5 | B18: =IF(D18=0, 0, IF(D18=1, A18, (D18*A18*$C$2)/($C$3*(1-D18)+$C$2*D18))) -> 5 | C18: =A18-B18 -> 0 | D18: 1 | G18: =IF(AND(E18>0,F18=0),1,IFERROR((E18/MW_beta)/((E18/MW_beta)+(F18/MW_hexoh)),""))
A20: Volumen de exceso
B21: Densidad | G21: Volumen de Exceso
A22: x1 | B22: 20 | C22: 30 | D22: 40 | E22: 50 | F22: 60 | G22: 20 | H22: 30 | I22: 40 | J22: 50 | K22: 60
A23: =G8 | B23: =densidad_viscosidad_puros!G25 -> 0.81883 | C23: =densidad_viscosidad_puros!G26 -> 0.81174 | D23: =densidad_viscosidad_puros!G27 -> 0.80455 | E23: =densidad_viscosidad_puros!G28 -> 0.79722 | F23: =densidad_viscosidad_puros!G29 -> 0.78971 | G23: =IFERROR((($A23*MW_beta)+((1-$A23)*MW_hexoh))/B23-(($A23*MW_beta/B$33)+((1-$A23)*MW_hexoh/B$23)),"") | H23: =IFERROR((($A23*MW_beta)+((1-$A23)*MW_hexoh))/C23-(($A23*MW_beta/C$33)+((1-$A23)*MW_hexoh/C$23)),"") | I23: =IFERROR((($A23*MW_beta)+((1-$A23)*MW_hexoh))/D23-(($A23*MW_beta/D$33)+((1-$A23)*MW_hexoh/D$23)),"") | J23: =IFERROR((($A23*MW_beta)+((1-$A23)*MW_hexoh))/E23-(($A23*MW_beta/E$33)+((1-$A23)*MW_hexoh/E$23)),"") | K23: =IFERROR((($A23*MW_beta)+((1-$A23)*MW_hexoh))/F23-(($A23*MW_beta/F$33)+((1-$A23)*MW_hexoh/F$23)),"")
